<robot name="kr210_r3300_k_ultra">
  <link
    name="base_link">
    <inertial>
      <origin
        xyz="-0.20775 0.00055823 0.12808"
        rpy="0 0 0" />
      <mass
        value="120.88" />
      <inertia
        ixx="4.0664"
        ixy="0.027244"
        ixz="0.91423"
        iyy="9.0263"
        iyz="-0.010672"
        izz="11.296" />
    </inertial>
    <visual>
      <origin
        xyz="0 0 0"
        rpy="0 0 0" />
      <geometry>
        <mesh
          filename="package://kuka_kr210_k_ultra_support/meshes/base_link.STL" />
      </geometry>
      <material
        name="">
        <color
          rgba="0.79216 0.81961 0.93333 1" />
      </material>
    </visual>
    <collision>
      <origin
        xyz="0 0 0"
        rpy="0 0 0" />
      <geometry>
        <mesh
          filename="package://kuka_kr210_k_ultra_support/meshes/base_link.STL" />
      </geometry>
    </collision>
  </link>
  <link
    name="a1">
    <inertial>
      <origin
        xyz="0.17966 -0.00038323 0.28193"
        rpy="0 0 0" />
      <mass
        value="146.16" />
      <inertia
        ixx="6.6882"
        ixy="-1.2586"
        ixz="-2.0837"
        iyy="19.319"
        iyz="-0.47947"
        izz="20.822" />
    </inertial>
    <visual>
      <origin
        xyz="0 0 0"
        rpy="0 0 0" />
      <geometry>
        <mesh
          filename="package://kuka_kr210_k_ultra_support/meshes/a1.STL" />
      </geometry>
      <material
        name="">
        <color
          rgba="0.79216 0.81961 0.93333 1" />
      </material>
    </visual>
    <collision>
      <origin
        xyz="0 0 0"
        rpy="0 0 0" />
      <geometry>
        <mesh
          filename="package://kuka_kr210_k_ultra_support/meshes/a1.STL" />
      </geometry>
    </collision>
  </link>
  <joint
    name="a1"
    type="continuous">
    <origin
      xyz="0 0 0.214635731952951"
      rpy="-6.12099546094239E-17 1.57900641784762E-18 0.0257908425371891" />
    <parent
      link="base_link" />
    <child
      link="a1" />
    <axis
      xyz="0 0 1" />
  </joint>
  <link
    name="a2">
    <inertial>
      <origin
        xyz="0.0055344 -0.26455 0.54174"
        rpy="0 0 0" />
      <mass
        value="126.48" />
      <inertia
        ixx="27.784"
        ixy="0.0076543"
        ixz="-0.04554"
        iyy="27.097"
        iyz="2.6237"
        izz="2.5095" />
    </inertial>
    <visual>
      <origin
        xyz="0 0 0"
        rpy="0 0 0" />
      <geometry>
        <mesh
          filename="package://kuka_kr210_k_ultra_support/meshes/a2.STL" />
      </geometry>
      <material
        name="">
        <color
          rgba="0.79216 0.81961 0.93333 1" />
      </material>
    </visual>
    <collision>
      <origin
        xyz="0 0 0"
        rpy="0 0 0" />
      <geometry>
        <mesh
          filename="package://kuka_kr210_k_ultra_support/meshes/a2.STL" />
      </geometry>
    </collision>
  </link>
  <joint
    name="a2"
    type="continuous">
    <origin
      xyz="0.749999999999672 0 0.375364268047466"
      rpy="0 -0.30368126812384 -1.64338795598164E-15" />
    <parent
      link="a1" />
    <child
      link="a2" />
    <axis
      xyz="0 -1 0" />
  </joint>
  <link
    name="a3">
    <inertial>
      <origin
        xyz="0.23647 -0.033853 -0.014837"
        rpy="0 0 0" />
      <mass
        value="85.793" />
      <inertia
        ixx="2.3827"
        ixy="-0.12099"
        ixz="0.23926"
        iyy="11.514"
        iyz="0.29194"
        izz="12.66" />
    </inertial>
    <visual>
      <origin
        xyz="0 0 0"
        rpy="0 0 0" />
      <geometry>
        <mesh
          filename="package://kuka_kr210_k_ultra_support/meshes/a3.STL" />
      </geometry>
      <material
        name="">
        <color
          rgba="0.79216 0.81961 0.93333 1" />
      </material>
    </visual>
    <collision>
      <origin
        xyz="0 0 0"
        rpy="0 0 0" />
      <geometry>
        <mesh
          filename="package://kuka_kr210_k_ultra_support/meshes/a3.STL" />
      </geometry>
    </collision>
  </link>
  <joint
    name="a3"
    type="continuous">
    <origin
      xyz="0 0 1.34999999999928"
      rpy="8.89335365055244E-19 0.222757009586188 -3.55734146022098E-18" />
    <parent
      link="a2" />
    <child
      link="a3" />
    <axis
      xyz="0 -1 0" />
  </joint>
  <link
    name="a4">
    <inertial>
      <origin
        xyz="-0.00092569 0.13446 4.0374E-07"
        rpy="0 0 0" />
      <mass
        value="5.1131" />
      <inertia
        ixx="0.062379"
        ixy="0.0009851"
        ixz="6.9632E-08"
        iyy="0.024696"
        iyz="-1.0902E-07"
        izz="0.061907" />
    </inertial>
    <visual>
      <origin
        xyz="0 0 0"
        rpy="0 0 0" />
      <geometry>
        <mesh
          filename="package://kuka_kr210_k_ultra_support/meshes/a4.STL" />
      </geometry>
      <material
        name="">
        <color
          rgba="0.79216 0.81961 0.93333 1" />
      </material>
    </visual>
    <collision>
      <origin
        xyz="0 0 0"
        rpy="0 0 0" />
      <geometry>
        <mesh
          filename="package://kuka_kr210_k_ultra_support/meshes/a4.STL" />
      </geometry>
    </collision>
  </link>
  <joint
    name="a4"
    type="continuous">
    <origin
      xyz="0.903648387390284 0 -0.0410000000002515"
      rpy="2.803833951231E-17 -0.0926032509080979 -1.57079632679491" />
    <parent
      link="a3" />
    <child
      link="a4" />
    <axis
      xyz="0 1 0" />
  </joint>
  <link
    name="a5">
    <inertial>
      <origin
        xyz="0.054314 0.037833 -2.6749E-05"
        rpy="0 0 0" />
      <mass
        value="11.495" />
      <inertia
        ixx="0.11957"
        ixy="0.027139"
        ixz="1.2206E-05"
        iyy="0.11876"
        iyz="2.1787E-05"
        izz="0.17595" />
    </inertial>
    <visual>
      <origin
        xyz="0 0 0"
        rpy="0 0 0" />
      <geometry>
        <mesh
          filename="package://kuka_kr210_k_ultra_support/meshes/a5.STL" />
      </geometry>
      <material
        name="">
        <color
          rgba="0.79216 0.81961 0.93333 1" />
      </material>
    </visual>
    <collision>
      <origin
        xyz="0 0 0"
        rpy="0 0 0" />
      <geometry>
        <mesh
          filename="package://kuka_kr210_k_ultra_support/meshes/a5.STL" />
      </geometry>
    </collision>
  </link>
  <joint
    name="a5"
    type="continuous">
    <origin
      xyz="0 0.296351612607003 0"
      rpy="-3.14159265358979 1.49089854131126 -1.5707963267949" />
    <parent
      link="a4" />
    <child
      link="a5" />
    <axis
      xyz="0 -1 0" />
  </joint>
  <link
    name="a6">
    <inertial>
      <origin
        xyz="0.020246 -1.2405E-05 3.8671E-05"
        rpy="0 0 0" />
      <mass
        value="0.64081" />
      <inertia
        ixx="0.0038456"
        ixy="-1.5728E-07"
        ixz="9.6859E-08"
        iyy="0.0019693"
        iyz="3.4977E-08"
        izz="0.0019665" />
    </inertial>
    <visual>
      <origin
        xyz="0 0 0"
        rpy="0 0 0" />
      <geometry>
        <mesh
          filename="package://kuka_kr210_k_ultra_support/meshes/a6.STL" />
      </geometry>
      <material
        name="">
        <color
          rgba="0.79216 0.81961 0.93333 1" />
      </material>
    </visual>
    <collision>
      <origin
        xyz="0 0 0"
        rpy="0 0 0" />
      <geometry>
        <mesh
          filename="package://kuka_kr210_k_ultra_support/meshes/a6.STL" />
      </geometry>
    </collision>
  </link>
  <joint
    name="a6"
    type="continuous">
    <origin
      xyz="0.205879405095406 0 0"
      rpy="-0.294130308640664 1.85918988537814E-15 5.87030424270552E-15" />
    <parent
      link="a5" />
    <child
      link="a6" />
    <axis
      xyz="-1 0 0" />
  </joint>
</robot>
