<robot
  name="KR210_R3300_K_ultra">
  <link
    name="base_link">
    <inertial>
      <origin
        xyz="-0.20775 0.12808 -0.00055823"
        rpy="0 0 0" />
      <mass
        value="120.88" />
      <inertia
        ixx="4.0664"
        ixy="0.91423"
        ixz="-0.027244"
        iyy="11.296"
        iyz="0.010672"
        izz="9.0263" />
    </inertial>
    <visual>
      <origin
        xyz="0 0 0"
        rpy="0 0 0" />
      <geometry>
        <mesh
          filename="package://kuka_kr210_support/meshes/kr210r3300kultra/base_link.STL" />
      </geometry>
      <material
        name="">
        <color
          rgba="0.79216 0.81961 0.93333 1" />
      </material>
    </visual>
    <collision>
      <origin
        xyz="0 0 0"
        rpy="0 0 0" />
      <geometry>
        <mesh
          filename="package://kuka_kr210_support/meshes/kr210r3300kultra/base_link.STL" />
      </geometry>
    </collision>
  </link>
  <link
    name="link_a1">
    <inertial>
      <origin
        xyz="0.17966 -0.010383 0.28193"
        rpy="0 0 0" />
      <mass
        value="146.16" />
      <inertia
        ixx="6.6882"
        ixy="-1.2586"
        ixz="-2.0837"
        iyy="19.319"
        iyz="-0.47947"
        izz="20.822" />
    </inertial>
    <visual>
      <origin
        xyz="0 0 0"
        rpy="0 0 0" />
      <geometry>
        <mesh
          filename="package://kuka_kr210_support/meshes/kr210r3300kultra/link_a1.STL" />
      </geometry>
      <material
        name="">
        <color
          rgba="0.79216 0.81961 0.93333 1" />
      </material>
    </visual>
    <collision>
      <origin
        xyz="0 0 0"
        rpy="0 0 0" />
      <geometry>
        <mesh
          filename="package://kuka_kr210_support/meshes/kr210r3300kultra/link_a1.STL" />
      </geometry>
    </collision>
  </link>
  <joint
    name="joint_a1"
    type="revolute">
    <origin
      xyz="0 0.01 0.21464"
      rpy="0.0 0.0 0.0" />
    <parent
      link="base_link" />
    <child
      link="link_a1" />
    <axis
      xyz="0 0 -1" />
    <limit
      lower="-3.2289"
      upper="3.2289"
      effort="0"
      velocity="1.8326" />
  </joint>
  <link
    name="link_a2">
    <inertial>
      <origin
        xyz="0.0055355 -0.26456 0.54174"
        rpy="0 0 0" />
      <mass
        value="126.48" />
      <inertia
        ixx="27.784"
        ixy="0.0076365"
        ixz="-0.045473"
        iyy="27.097"
        iyz="2.6236"
        izz="2.5095" />
    </inertial>
    <visual>
      <origin
        xyz="0 0 0"
        rpy="0 0 0" />
      <geometry>
        <mesh
          filename="package://kuka_kr210_support/meshes/kr210r3300kultra/link_a2.STL" />
      </geometry>
      <material
        name="">
        <color
          rgba="0.79216 0.81961 0.93333 1" />
      </material>
    </visual>
    <collision>
      <origin
        xyz="0 0 0"
        rpy="0 0 0" />
      <geometry>
        <mesh
          filename="package://kuka_kr210_support/meshes/kr210r3300kultra/link_a2.STL" />
      </geometry>
    </collision>
  </link>
  <joint
    name="joint_a2"
    type="revolute">
    <origin
      xyz="0.75 -0.01 0.37536"
      rpy="0.0 1.570796 0.0" />
    <parent
      link="link_a1" />
    <child
      link="link_a2" />
    <axis
      xyz="0 1 0" />
    <limit
      lower="-2.0944"
      upper="1.2217"
      effort="0"
      velocity="1.7628" />
  </joint>
  <link
    name="link_a3">
    <inertial>
      <origin
        xyz="0.23647 -0.043853 -0.014836"
        rpy="0 0 0" />
      <mass
        value="85.793" />
      <inertia
        ixx="2.3827"
        ixy="-0.12099"
        ixz="0.23925"
        iyy="11.514"
        iyz="0.29194"
        izz="12.66" />
    </inertial>
    <visual>
      <origin
        xyz="0 0 0"
        rpy="0 0 0" />
      <geometry>
        <mesh
          filename="package://kuka_kr210_support/meshes/kr210r3300kultra/link_a3.STL" />
      </geometry>
      <material
        name="">
        <color
          rgba="0.79216 0.81961 0.93333 1" />
      </material>
    </visual>
    <collision>
      <origin
        xyz="0 0 0"
        rpy="0 0 0" />
      <geometry>
        <mesh
          filename="package://kuka_kr210_support/meshes/kr210r3300kultra/link_a3.STL" />
      </geometry>
    </collision>
  </link>
  <joint
    name="joint_a3"
    type="revolute">
    <origin
      xyz="0 0.01 1.35"
      rpy="0.0 -1.570796 0.0" />
    <parent
      link="link_a2" />
    <child
      link="link_a3" />
    <axis
      xyz="0 1 0" />
    <limit
      lower="-2.0944"
      upper="2.7053"
      effort="0"
      velocity="1.8675" />
  </joint>
  <link
    name="link_a4">
    <inertial>
      <origin
        xyz="-0.0009255 0.11699 3.1061E-07"
        rpy="0 0 0" />
      <mass
        value="5.113" />
      <inertia
        ixx="0.062378"
        ixy="0.00098507"
        ixz="5.8079E-08"
        iyy="0.024696"
        iyz="-1.69E-07"
        izz="0.061907" />
    </inertial>
    <visual>
      <origin
        xyz="0 0 0"
        rpy="0 0 0" />
      <geometry>
        <mesh
          filename="package://kuka_kr210_support/meshes/kr210r3300kultra/link_a4.STL" />
      </geometry>
      <material
        name="">
        <color
          rgba="0.79216 0.81961 0.93333 1" />
      </material>
    </visual>
    <collision>
      <origin
        xyz="0 0 0"
        rpy="0 0 0" />
      <geometry>
        <mesh
          filename="package://kuka_kr210_support/meshes/kr210r3300kultra/link_a4.STL" />
      </geometry>
    </collision>
  </link>
  <joint
    name="joint_a4"
    type="revolute">
    <origin
      xyz="0.92112 -0.01 -0.041"
      rpy="0.0 0.0 -1.570796" />
    <parent
      link="link_a3" />
    <child
      link="link_a4" />
    <axis
      xyz="0 -1 0" />
    <limit
      lower="-6.1087"
      upper="6.1087"
      effort="0"
      velocity="2.3736" />
  </joint>
  <link
    name="link_a5">
    <inertial>
      <origin
        xyz="0.054314 0.027833 -2.6352E-05"
        rpy="0 0 0" />
      <mass
        value="11.495" />
      <inertia
        ixx="0.11957"
        ixy="0.027139"
        ixz="1.2241E-05"
        iyy="0.11876"
        iyz="2.1645E-05"
        izz="0.17595" />
    </inertial>
    <visual>
      <origin
        xyz="0 0 0"
        rpy="0 0 0" />
      <geometry>
        <mesh
          filename="package://kuka_kr210_support/meshes/kr210r3300kultra/link_a5.STL" />
      </geometry>
      <material
        name="">
        <color
          rgba="0.79216 0.81961 0.93333 1" />
      </material>
    </visual>
    <collision>
      <origin
        xyz="0 0 0"
        rpy="0 0 0" />
      <geometry>
        <mesh
          filename="package://kuka_kr210_support/meshes/kr210r3300kultra/link_a5.STL" />
      </geometry>
    </collision>
  </link>
  <joint
    name="joint_a5"
    type="revolute">
    <origin
      xyz="-0.01 0.27888 0"
      rpy="0.0 0.0 1.570796" />
    <parent
      link="link_a4" />
    <child
      link="link_a5" />
    <axis
      xyz="0 1 0" />
    <limit
      lower="-2.138"
      upper="2.138"
      effort="0"
      velocity="2.2515" />
  </joint>
  <link
    name="link_a6">
    <inertial>
      <origin
        xyz="0.021126 -0.010012 3.8671E-05"
        rpy="0 0 0" />
      <mass
        value="0.64081" />
      <inertia
        ixx="0.0038456"
        ixy="-1.5728E-07"
        ixz="9.6859E-08"
        iyy="0.0019693"
        iyz="3.5182E-08"
        izz="0.0019665" />
    </inertial>
    <visual>
      <origin
        xyz="0 0 0"
        rpy="0 0 0" />
      <geometry>
        <mesh
          filename="package://kuka_kr210_support/meshes/kr210r3300kultra/link_a6.STL" />
      </geometry>
      <material
        name="">
        <color
          rgba="0.79216 0.81961 0.93333 1" />
      </material>
    </visual>
    <collision>
      <origin
        xyz="0 0 0"
        rpy="0 0 0" />
      <geometry>
        <mesh
          filename="package://kuka_kr210_support/meshes/kr210r3300kultra/link_a6.STL" />
      </geometry>
    </collision>
  </link>
  <joint
    name="joint_a6"
    type="revolute">
    <origin
      xyz="0.205 0.0 0.0011076"
      rpy="0.0 0 0" />
    <parent
      link="link_a5" />
    <child
      link="link_a6" />
    <axis
      xyz="-1 0 0" />
    <limit
      lower="-6.1087"
      upper="6.1087"
      effort="0"
      velocity="3.5954" />
  </joint>
</robot>
